<?xml version="1.0" encoding="UTF-8"?>
<sdf version="1.9">
  <model name="custom_quad">

    <pose>0 0 0.24 0 0 0</pose>
    <static>false</static>
    <self_collide>false</self_collide>

    <!-- Corpo principale -->
    <link name="base_link">
      <inertial>
        <mass>2.0</mass>
        <inertia>
          <ixx>0.02166666666666667</ixx>
          <iyy>0.02166666666666667</iyy>
          <izz>0.04</izz>
          <ixy>0</ixy>
          <ixz>0</ixz>
          <iyz>0</iyz>
        </inertia>
      </inertial>

      <visual name="body_visual">
        <geometry>
          <box>
            <size>0.3 0.3 0.05</size>
          </box>
        </geometry>
        <material>
          <ambient>1 0 0 1</ambient>
          <diffuse>1 0 0 1</diffuse>
        </material>
      </visual>

      <collision name="body_collision">
        <geometry>
          <box>
            <size>0.3 0.3 0.05</size>
          </box>
        </geometry>
      </collision>

      <!-- Sensori -->
      <sensor name="imu_sensor" type="imu">
        <always_on>1</always_on>
        <update_rate>250</update_rate>
        <imu>
          <angular_velocity>
            <x><noise type="gaussian"><mean>0</mean><stddev>0.0008726646</stddev></noise></x>
            <y><noise type="gaussian"><mean>0</mean><stddev>0.0008726646</stddev></noise></y>
            <z><noise type="gaussian"><mean>0</mean><stddev>0.0008726646</stddev></noise></z>
          </angular_velocity>
          <linear_acceleration>
            <x><noise type="gaussian"><mean>0</mean><stddev>0.00637</stddev></noise></x>
            <y><noise type="gaussian"><mean>0</mean><stddev>0.00637</stddev></noise></y>
            <z><noise type="gaussian"><mean>0</mean><stddev>0.00686</stddev></noise></z>
          </linear_acceleration>
        </imu>
      </sensor>

      <sensor name="magnetometer_sensor" type="magnetometer">
        <always_on>1</always_on>
        <update_rate>100</update_rate>
        <magnetometer>
          <x><noise type="gaussian"><stddev>0.0001</stddev></noise></x>
          <y><noise type="gaussian"><stddev>0.0001</stddev></noise></y>
          <z><noise type="gaussian"><stddev>0.0001</stddev></noise></z>
        </magnetometer>
      </sensor>

      <sensor name="air_pressure_sensor" type="air_pressure">
        <always_on>1</always_on>
        <update_rate>50</update_rate>
        <air_pressure>
          <pressure>
            <noise type="gaussian"><mean>0</mean><stddev>3</stddev></noise>
          </pressure>
        </air_pressure>
      </sensor>

      <sensor name="navsat_sensor" type="navsat">
        <always_on>1</always_on>
        <update_rate>30</update_rate>
      </sensor>
    </link>

    <!-- Rotori -->
    <link name="rotor_0">
      <pose>0.174 -0.174 0.06 0 0 0</pose>
      <inertial>
        <mass>0.02</mass>
        <inertia><ixx>1e-5</ixx><iyy>1e-5</iyy><izz>1e-5</izz></inertia>
      </inertial>
      <visual name="rotor0_visual">
        <geometry>
          <cylinder><radius>0.05</radius><length>0.01</length></cylinder>
        </geometry>
        <material><ambient>0 0 1 1</ambient><diffuse>0 0 1 1</diffuse></material>
      </visual>
      <collision name="rotor0_collision">
        <geometry>
          <cylinder><radius>0.05</radius><length>0.01</length></cylinder>
        </geometry>
      </collision>
    </link>

    <joint name="rotor_0_joint" type="revolute">
      <parent>base_link</parent>
      <child>rotor_0</child>
      <axis><xyz>0 0 1</xyz></axis>
    </joint>

    <link name="rotor_1">
      <pose>-0.174 0.174 0.06 0 0 0</pose>
      <inertial>
        <mass>0.02</mass>
        <inertia><ixx>1e-5</ixx><iyy>1e-5</iyy><izz>1e-5</izz></inertia>
      </inertial>
      <visual name="rotor1_visual">
        <geometry>
          <cylinder><radius>0.05</radius><length>0.01</length></cylinder>
        </geometry>
        <material><ambient>0 0 1 1</ambient><diffuse>0 0 1 1</diffuse></material>
      </visual>
      <collision name="rotor1_collision">
        <geometry>
          <cylinder><radius>0.05</radius><length>0.01</length></cylinder>
        </geometry>
      </collision>
    </link>

    <joint name="rotor_1_joint" type="revolute">
      <parent>base_link</parent>
      <child>rotor_1</child>
      <axis><xyz>0 0 1</xyz></axis>
    </joint>

    <link name="rotor_2">
      <pose>0.174 0.174 0.06 0 0 0</pose>
      <inertial>
        <mass>0.02</mass>
        <inertia><ixx>1e-5</ixx><iyy>1e-5</iyy><izz>1e-5</izz></inertia>
      </inertial>
      <visual name="rotor2_visual">
        <geometry>
          <cylinder><radius>0.05</radius><length>0.01</length></cylinder>
        </geometry>
        <material><ambient>0 0 1 1</ambient><diffuse>0 0 1 1</diffuse></material>
      </visual>
      <collision name="rotor2_collision">
        <geometry>
          <cylinder><radius>0.05</radius><length>0.01</length></cylinder>
        </geometry>
      </collision>
    </link>

    <joint name="rotor_2_joint" type="revolute">
      <parent>base_link</parent>
      <child>rotor_2</child>
      <axis><xyz>0 0 1</xyz></axis>
    </joint>

    <link name="rotor_3">
      <pose>-0.174 -0.174 0.06 0 0 0</pose>
      <inertial>
        <mass>0.02</mass>
        <inertia><ixx>1e-5</ixx><iyy>1e-5</iyy><izz>1e-5</izz></inertia>
      </inertial>
      <visual name="rotor3_visual">
        <geometry>
          <cylinder><radius>0.05</radius><length>0.01</length></cylinder>
        </geometry>
        <material><ambient>0 0 1 1</ambient><diffuse>0 0 1 1</diffuse></material>
      </visual>
      <collision name="rotor3_collision">
        <geometry>
          <cylinder><radius>0.05</radius><length>0.01</length></cylinder>
        </geometry>
      </collision>
    </link>

    <joint name="rotor_3_joint" type="revolute">
      <parent>base_link</parent>
      <child>rotor_3</child>
      <axis><xyz>0 0 1</xyz></axis>
    </joint>

     <plugin filename="gz-sim-multicopter-motor-model-system" name="gz::sim::systems::MulticopterMotorModel">
      <jointName>rotor_0_joint</jointName>
      <linkName>rotor_0</linkName>
      <turningDirection>ccw</turningDirection>
      <timeConstantUp>0.0125</timeConstantUp>
      <timeConstantDown>0.025</timeConstantDown>
      <maxRotVelocity>1000.0</maxRotVelocity>
      <motorConstant>8.54858e-06</motorConstant>
      <momentConstant>0.016</momentConstant>
      <commandSubTopic>command/motor_speed</commandSubTopic>
      <motorNumber>0</motorNumber>
      <rotorDragCoefficient>8.06428e-05</rotorDragCoefficient>
      <rollingMomentCoefficient>1e-06</rollingMomentCoefficient>
      <rotorVelocitySlowdownSim>10</rotorVelocitySlowdownSim>
      <motorType>velocity</motorType>
    </plugin>
    <plugin filename="gz-sim-multicopter-motor-model-system" name="gz::sim::systems::MulticopterMotorModel">
      <jointName>rotor_1_joint</jointName>
      <linkName>rotor_1</linkName>
      <turningDirection>ccw</turningDirection>
      <timeConstantUp>0.0125</timeConstantUp>
      <timeConstantDown>0.025</timeConstantDown>
      <maxRotVelocity>1000.0</maxRotVelocity>
      <motorConstant>8.54858e-06</motorConstant>
      <momentConstant>0.016</momentConstant>
      <commandSubTopic>command/motor_speed</commandSubTopic>
      <motorNumber>1</motorNumber>
      <rotorDragCoefficient>8.06428e-05</rotorDragCoefficient>
      <rollingMomentCoefficient>1e-06</rollingMomentCoefficient>
      <rotorVelocitySlowdownSim>10</rotorVelocitySlowdownSim>
      <motorType>velocity</motorType>
    </plugin>
    <plugin filename="gz-sim-multicopter-motor-model-system" name="gz::sim::systems::MulticopterMotorModel">
      <jointName>rotor_2_joint</jointName>
      <linkName>rotor_2</linkName>
      <turningDirection>cw</turningDirection>
      <timeConstantUp>0.0125</timeConstantUp>
      <timeConstantDown>0.025</timeConstantDown>
      <maxRotVelocity>1000.0</maxRotVelocity>
      <motorConstant>8.54858e-06</motorConstant>
      <momentConstant>0.016</momentConstant>
      <commandSubTopic>command/motor_speed</commandSubTopic>
      <motorNumber>2</motorNumber>
      <rotorDragCoefficient>8.06428e-05</rotorDragCoefficient>
      <rollingMomentCoefficient>1e-06</rollingMomentCoefficient>
      <rotorVelocitySlowdownSim>10</rotorVelocitySlowdownSim>
      <motorType>velocity</motorType>
    </plugin>
    <plugin filename="gz-sim-multicopter-motor-model-system" name="gz::sim::systems::MulticopterMotorModel">
      <jointName>rotor_3_joint</jointName>
      <linkName>rotor_3</linkName>
      <turningDirection>cw</turningDirection>
      <timeConstantUp>0.0125</timeConstantUp>
      <timeConstantDown>0.025</timeConstantDown>
      <maxRotVelocity>1000.0</maxRotVelocity>
      <motorConstant>8.54858e-06</motorConstant>
      <momentConstant>0.016</momentConstant>
      <commandSubTopic>command/motor_speed</commandSubTopic>
      <motorNumber>3</motorNumber>
      <rotorDragCoefficient>8.06428e-05</rotorDragCoefficient>
      <rollingMomentCoefficient>1e-06</rollingMomentCoefficient>
      <rotorVelocitySlowdownSim>10</rotorVelocitySlowdownSim>
      <motorType>velocity</motorType>
    </plugin>
  </model>
</sdf>
